<?xml version="1.0" ?>
<!-- =================================================================================== -->
<!-- |    EDITING THIS FILE BY HAND IS NOT RECOMMENDED                                 | -->
<!-- =================================================================================== -->
<robot name="ur10e_lf" xmlns:xacro="http://www.ros.org/wiki/xacro">
<!-- =================================================================================== -->
  <!-- links: main serial chain -->

  <link name="lh_wrist"></link>
  <link name="lh_wrist_tem1"></link>
  <link name="lh_wrist_tem2"></link>
  <link name="lh_wrist_tem3"></link>
  <link name="lh_wrist_tem4"></link>
  <link name="lh_wrist_tem5"></link>


  <link name="lh_palm">
    <inertial>
      <origin rpy="0 0 0" xyz="0 0 0.0"/>
      <mass value="0.0"/>
      <inertia ixx="0.0" ixy="0.0" ixz="0.0" iyy="0.0" iyz="0.0" izz="0.0"/>
    </inertial>
    <visual>
      <origin rpy="0 0 0" xyz="0 0 0"/>
      <geometry name="lh_palm_visual">
        <mesh filename="package://shadowhand/components/palm/palm_E3M5.dae" scale="-0.001 0.001 0.001"/>
      </geometry>
      <material name="Grey"/>
    </visual>
    <collision>
      <origin rpy="0 0 0" xyz="-0.011 0.0085 0.038"/>
      <geometry name="lh_palm_collision_geom">
        <box size="0.062 0.007 0.098"/>
      </geometry>
    </collision>
    <collision>
      <origin rpy="0 0 0" xyz="0.002 -0.0035 0.038"/>
      <geometry>
        <box size="0.036 0.017 0.098"/>
      </geometry>
    </collision>
    <!-- palm complement below first finger -->
    <collision>
      <origin rpy="0 0 0" xyz="-0.029 -0.0035 0.082"/>
      <geometry>
        <box size="0.026 0.017 0.010"/>
      </geometry>
    </collision>
    <collision>
      <origin rpy="0.2 0 -0.25" xyz="-0.0265 -0.001 0.070"/>
      <geometry>
        <box size="0.026 0.014 0.018"/>
      </geometry>
    </collision>
    <!-- thumb pulp side -->
    <collision>
      <origin rpy="0 0 0" xyz="-0.0315 -0.0085 0.001"/>
      <geometry>
        <box size="0.021 0.027 0.024"/>
      </geometry>
    </collision>
    <!-- thumb pulp central -->
    <collision>
      <origin rpy="0 0 0.48" xyz="-0.0125 -0.015 0.009"/>
      <geometry>
        <box size="0.022 0.005 0.040"/>
      </geometry>
    </collision>
    <!-- above middle finger-->
    <collision>
      <origin rpy="0 0 0" xyz="-0.011 0 0.089"/>
      <geometry>
        <box size="0.018 0.024 0.004"/>
      </geometry>
    </collision>
    <!-- metacarpal side-->
    <collision>
      <origin rpy="0 0 0" xyz="0.03 0 0.009"/>
      <geometry>
        <box size="0.020 0.024 0.040"/>
      </geometry>
    </collision>
  </link>

<!-- =================================================================================== -->
  <link name="lh_grasp_ref_center">
  </link>
  <joint name="lh_grasp_ref" type="fixed">
    <parent link="lh_palm"/>
    <child link="lh_grasp_ref_center"/>
    <origin rpy="0 0 0" xyz="0.0 0 0.095"/>
    <axis xyz="0 0 1"/>
  </joint>

<!-- =================================================================================== -->
  <link name="lh_ffknuckle">
    <inertial>
      <origin rpy="0 0 0" xyz="0 0 0"/>
      <mass value="0.0"/>
      <inertia ixx="0.0" ixy="0.0" ixz="0.0" iyy="0.0" iyz="0.0" izz="0.0"/>
    </inertial>
    <visual>
      <origin rpy="0 0 0" xyz="0 0 0.0005"/>
      <geometry name="lh_ffknuckle_visual">
        <mesh filename="package://shadowhand/components/f_knuckle/f_knuckle_E3M5.dae" scale="0.001 0.001 0.001"/>
      </geometry>
      <material name="LightGrey"/>
    </visual>
    <collision>
      <origin rpy="0 1.5708 0" xyz="0 0 0"/>
      <geometry name="lh_ffknuckle_collision_geom">
        <cylinder length="0.014" radius="0.007"/>
      </geometry>
    </collision>
  </link>

  <joint name="lh_FFJ4" type="revolute">
    <parent link="lh_palm"/>
    <child link="lh_ffknuckle"/>
    <!--<origin xyz="0.033 0 0.095" rpy="0 0 0" />-->
    <origin rpy="0 0 0" xyz="-0.033 0 0.095"/>
    <axis xyz="0 1 0"/>
    <limit effort="200" lower="-0.3490658503988659" upper="0.3490658503988659" velocity="2.0"/>
    <dynamics damping="0.1"/>
  </joint>

<!-- =================================================================================== -->
  <link name="lh_ffproximal">
    <inertial>
      <mass value="0.0"/>
      <origin xyz="0 0 0.0"/>
      <inertia ixx="0.0" ixy="0.0" ixz="0.0" iyy="0.0" iyz="0.0" izz="0.0"/>
    </inertial>
    <visual>
      <origin rpy="-1.57079632679 0 0" xyz="0 0 0"/>
      <geometry name="lh_ffproximal_visual">
        <mesh filename="package://shadowhand/components/f_proximal/f_proximal_E3M5.dae" scale="0.001 0.001 0.001"/>
      </geometry>
      <material name="Grey"/>
    </visual>
    <collision>
      <origin rpy="0 0 0" xyz="0 0 0.025"/>
      <geometry name="lh_ffproximal_collision_geom">
        <cylinder length="0.040" radius="0.007"/>
      </geometry>
    </collision>
  </link>
  <joint name="lh_FFJ3" type="revolute">
    <parent link="lh_ffknuckle"/>
    <child link="lh_ffproximal"/>
    <origin rpy="0 0 0" xyz="0 0 0"/>
    <axis xyz="1 0 0"/>
    <limit effort="200" lower="-0.2617993877991494" upper="1.5707963267948966" velocity="2.0"/>
    <dynamics damping="0.1"/>
  </joint>

<!-- =================================================================================== -->
  <link name="lh_ffmiddle">
    <inertial>
      <origin rpy="0 0 0" xyz="0 0 0.0"/>
      <mass value="0.0"/>
      <inertia ixx="0.0" ixy="0.0" ixz="0.0" iyy="0.0" iyz="0.0" izz="0.0"/>
    </inertial>
    <visual>
      <origin rpy="-1.57079632679 0 0" xyz="0 0 0"/>
      <geometry name="lh_ffmiddle_visual">
        <mesh filename="package://shadowhand/components/f_middle/f_middle_E3M5.dae" scale="0.001 0.001 0.001"/>
      </geometry>
      <material name="Grey"/>
    </visual>
    <collision>
      <origin rpy="0 0 0" xyz="0 0 0.0125"/>
      <geometry name="lh_ffmiddle_collision_geom">
        <cylinder length="0.025" radius="0.007"/>
      </geometry>
    </collision>
    <collision> 
      <origin rpy="0 0 0" xyz="0 0 0.0"/>
      <geometry>
        <sphere radius="0.007"/>
      </geometry>
    </collision>
    <collision>
      <origin rpy="0 0 0" xyz="0 0 0.025"/>
      <geometry>
        <sphere radius="0.007"/>
      </geometry>
    </collision>
  </link>

  <joint name="lh_FFJ2" type="revolute">
    <parent link="lh_ffproximal"/>
    <child link="lh_ffmiddle"/>
    <origin rpy="0 0 0" xyz="0 0 0.045"/>
    <axis xyz="1 0 0"/>
    <limit effort="200" lower="0" upper="1.5707963267948966" velocity="2.0"/>
    <dynamics damping="0.1"/>
  </joint>


  <link name="lh_ffdistal">
    <inertial>
      <mass value="0.0"/>
      <origin xyz="0 0 0.0"/>
      <inertia ixx="0.0" ixy="0.0" ixz="0.0" iyy="0.0" iyz="0.0" izz="0.0"/>
    </inertial>
    <visual>
      <origin rpy="0.0 1.57079632679 1.57079632679" xyz="0.0 0.0 0.016"/>
      <geometry>
        <mesh filename="package://bio_tac/meshes/biotac/merged_tip.obj"/>
      </geometry>
    </visual>
    <collision>
      <origin rpy="0.0 1.57079632679 0.0" xyz="0.0 0.0 0.016"/>
        <geometry>
          <mesh filename="package://bio_tac/meshes/biotac/merged_tip.obj"/>
        </geometry>
    </collision>
  </link>


  <joint name="lh_FFJ1" type="revolute">
    <parent link="lh_ffmiddle"/>
    <child link="lh_ffdistal"/>
    <origin rpy="0 0 0" xyz="0 0 0.025"/>
    <axis xyz="1 0 0"/>
    <!-- standard distal joint -->
    <limit effort="2" lower="0" upper="1.5707963267948966" velocity="2.0"/>
    <dynamics damping="0.1"/>
  </joint>


  <link name="lh_fftip">
  </link>
  <joint name="lh_FFtip" type="fixed">
    <parent link="lh_ffdistal"/>
    <child link="lh_fftip"/>
    <origin rpy="0 0 0" xyz="0 0 0.026"/>
  </joint>

<!-- =================================================================================== -->
  <link name="lh_mfknuckle">
    <inertial>
      <origin rpy="0 0 0" xyz="0 0 0"/>
      <mass value="0.0"/>
      <inertia ixx="0.0" ixy="0.0" ixz="0.0" iyy="0.0" iyz="0.0" izz="0.0"/>
    </inertial>
    <visual>
      <origin rpy="0 0 0" xyz="0 0 0.0005"/>
      <geometry name="lh_mfknuckle_visual">
        <mesh filename="package://shadowhand/components/f_knuckle/f_knuckle_E3M5.dae" scale="0.001 0.001 0.001"/>
      </geometry>
      <material name="LightGrey"/>
    </visual>
    <collision>
      <origin rpy="0 1.5708 0" xyz="0 0 0"/>
      <geometry name="lh_mfknuckle_collision_geom">
        <cylinder length="0.014" radius="0.007"/>
      </geometry>
    </collision>
  </link>
  <joint name="lh_MFJ4" type="revolute">
    <parent link="lh_palm"/>
    <child link="lh_mfknuckle"/>
    <!--<origin xyz="0.033 0 0.095" rpy="0 0 0" />-->
    <origin rpy="0 0 0" xyz="-0.011 0 0.099"/>
    <axis xyz="0 1 0"/>
    <limit effort="2" lower="-0.3490658503988659" upper="0.3490658503988659" velocity="2.0"/>
    <dynamics damping="0.1"/>
  </joint>

<!-- =================================================================================== -->

  <link name="lh_mfproximal">
    <inertial>
      <mass value="0.0"/>
      <origin xyz="0 0 0.0"/>
      <inertia ixx="0.0" ixy="0.0" ixz="0.0" iyy="0.0" iyz="0.0" izz="0.0"/>
    </inertial>
    <visual>
      <!--origin rpy="0 0 0" xyz="0 0 0"/-->
      <origin rpy="-1.57079632679 0 0" xyz="0 0 0"/>
      <geometry name="lh_mfproximal_visual">
        <mesh filename="package://shadowhand/components/f_proximal/f_proximal_E3M5.dae" scale="0.001 0.001 0.001"/>
      </geometry>
      <material name="Grey"/>
    </visual>
    <collision>
      <origin rpy="0 0 0" xyz="0 0 0.025"/>
      <geometry name="lh_mfproximal_collision_geom">
        <cylinder length="0.040" radius="0.007"/>
      </geometry>
    </collision>
  </link>
  <joint name="lh_MFJ3" type="revolute">
    <parent link="lh_mfknuckle"/>
    <child link="lh_mfproximal"/>
    <origin rpy="0 0 0" xyz="0 0 0"/>
    <axis xyz="1 0 0"/>
    <limit effort="2" lower="-0.2617993877991494" upper="1.5707963267948966" velocity="2.0"/>
    <dynamics damping="0.1"/>
  </joint>

<!-- =================================================================================== -->
  <link name="lh_mfmiddle">
    <inertial>
      <origin rpy="0 0 0" xyz="0 0 0.0"/>
      <mass value="0.0"/>
      <inertia ixx="0.0" ixy="0.0" ixz="0.0" iyy="0.0" iyz="0.0" izz="0.0"/>
    </inertial>
    <visual>
      <!--origin rpy="0 0 0" xyz="0 0 0"/-->
      <origin rpy="-1.57079632679 0 0" xyz="0 0 0"/>
      <geometry name="lh_mfmiddle_visual">
        <mesh filename="package://shadowhand/components/f_middle/f_middle_E3M5.dae" scale="0.001 0.001 0.001"/>
      </geometry>
      <material name="Grey"/>
    </visual>
    <collision>
      <origin rpy="0 0 0" xyz="0 0 0.0125"/>
      <geometry name="lh_mfmiddle_collision_geom">
        <cylinder length="0.025" radius="0.007"/>
      </geometry>
    </collision>
    <collision>
      <origin rpy="0 0 0" xyz="0 0 0.0"/>
      <geometry>
        <sphere radius="0.007"/>
      </geometry>
    </collision>
    <collision>
      <origin rpy="0 0 0" xyz="0 0 0.025"/>
      <geometry>
        <sphere radius="0.007"/>
      </geometry>
    </collision>
  </link>
  <joint name="lh_MFJ2" type="revolute">
    <parent link="lh_mfproximal"/>
    <child link="lh_mfmiddle"/>
    <origin rpy="0 0 0" xyz="0 0 0.045"/>
    <axis xyz="1 0 0"/>
    <limit effort="2" lower="0" upper="1.5707963267948966" velocity="2.0"/>
    <dynamics damping="0.1"/>
  </joint>

  <link name="lh_mfdistal">
    <inertial>
      <mass value="0.0"/>
      <origin xyz="0 0 0.0"/>
      <inertia ixx="0.0" ixy="0.0" ixz="0.0" iyy="0.0" iyz="0.0" izz="0.0"/>
    </inertial>
    <visual>
      <origin rpy="0.0 1.57079632679 1.57079632679" xyz="0.0 0.0 0.016"/>
      <geometry>
        <mesh filename="package://bio_tac/meshes/biotac/merged_tip.obj"/>
      </geometry>
    </visual>
    <collision>
      <origin rpy="0.0 1.57079632679 0.0" xyz="0.0 0.0 0.016"/>
        <geometry>
          <mesh filename="package://bio_tac/meshes/biotac/merged_tip.obj"/>
        </geometry>
    </collision>
  </link>

  <joint name="lh_MFJ1" type="revolute">
    <parent link="lh_mfmiddle"/>
    <child link="lh_mfdistal"/>
    <origin rpy="0 0 0" xyz="0 0 0.025"/>
    <axis xyz="1 0 0"/>
    <limit effort="2" lower="0" upper="1.5707963267948966" velocity="2.0"/>
    <dynamics damping="0.1"/>
  </joint>


  <link name="lh_mftip">
  </link>
  <joint name="lh_MFtip" type="fixed">
    <parent link="lh_mfdistal"/>
    <child link="lh_mftip"/>
    <origin rpy="0 0 0" xyz="0 0 0.026"/>
  </joint>

<!-- =================================================================================== -->
  <link name="lh_rfknuckle">
    <inertial>
      <origin rpy="0 0 0" xyz="0 0 0"/>
      <mass value="0.0"/>
      <inertia ixx="0.0" ixy="0.0" ixz="0.0" iyy="0.0" iyz="0.0" izz="0.0"/>
    </inertial>
    <visual>
      <origin rpy="0 0 0" xyz="0 0 0.0005"/>
      <geometry name="lh_rfknuckle_visual">
        <mesh filename="package://shadowhand/components/f_knuckle/f_knuckle_E3M5.dae" scale="0.001 0.001 0.001"/>
      </geometry>
      <material name="LightGrey"/>
    </visual>
    <collision>
      <origin rpy="0 1.5708 0" xyz="0 0 0"/>
      <geometry name="lh_rfknuckle_collision_geom">
        <cylinder length="0.014" radius="0.007"/>
      </geometry>
    </collision>
  </link>
  <joint name="lh_RFJ4" type="revolute">
    <parent link="lh_palm"/>
    <child link="lh_rfknuckle"/>
    <origin rpy="0 0 0" xyz="0.011 0 0.095"/>
    <axis xyz="0 -1 0"/>
    <limit effort="2" lower="-0.3490658503988659" upper="0.3490658503988659" velocity="2.0"/>
    <dynamics damping="0.1"/>
  </joint>

<!-- =================================================================================== -->
  <link name="lh_rfproximal">
    <inertial>
      <mass value="0.0"/>
      <origin xyz="0 0 0.0"/>
      <inertia ixx="0.0" ixy="0.0" ixz="0.0" iyy="0.0" iyz="0.0" izz="0.0"/>
    </inertial>
    <visual>
      <origin rpy="-1.57079632679 0 0" xyz="0 0 0"/>
      <geometry name="lh_rfproximal_visual">
        <mesh filename="package://shadowhand/components/f_proximal/f_proximal_E3M5.dae" scale="0.001 0.001 0.001"/>
      </geometry>
      <material name="Grey"/>
    </visual>
    <collision>
      <origin rpy="0 0 0" xyz="0 0 0.025"/>
      <geometry name="lh_rfproximal_collision_geom">
        <cylinder length="0.040" radius="0.007"/>
      </geometry>
    </collision>
  </link>
  <joint name="lh_RFJ3" type="revolute">
    <parent link="lh_rfknuckle"/>
    <child link="lh_rfproximal"/>
    <origin rpy="0 0 0" xyz="0 0 0"/>
    <axis xyz="1 0 0"/>
    <limit effort="2" lower="-0.2617993877991494" upper="1.5707963267948966" velocity="2.0"/>
    <dynamics damping="0.1"/>
  </joint>

<!-- =================================================================================== -->
  <link name="lh_rfmiddle">
    <inertial>
      <origin rpy="0 0 0" xyz="0 0 0.0"/>
      <mass value="0.0"/>
      <inertia ixx="0.0" ixy="0.0" ixz="0.0" iyy="0.0" iyz="0.0" izz="0.0"/>
    </inertial>
    <visual>
      <!--origin rpy="0 0 0" xyz="0 0 0"/-->
      <origin rpy="-1.57079632679 0 0" xyz="0 0 0"/>
      <geometry name="lh_rfmiddle_visual">
        <mesh filename="package://shadowhand/components/f_middle/f_middle_E3M5.dae" scale="0.001 0.001 0.001"/>
      </geometry>
      <material name="Grey"/>
    </visual>
    <collision>
      <origin rpy="0 0 0" xyz="0 0 0.0125"/>
      <geometry name="lh_rfmiddle_collision_geom">
        <cylinder length="0.025" radius="0.007"/>
      </geometry>
    </collision>
    <collision>
      <origin rpy="0 0 0" xyz="0 0 0.0"/>
      <geometry>
        <sphere radius="0.007"/>
      </geometry>
    </collision>
    <collision>
      <origin rpy="0 0 0" xyz="0 0 0.025"/>
      <geometry>
        <sphere radius="0.007"/>
      </geometry>
    </collision>
  </link>
  <joint name="lh_RFJ2" type="revolute">
    <parent link="lh_rfproximal"/>
    <child link="lh_rfmiddle"/>
    <origin rpy="0 0 0" xyz="0 0 0.045"/>
    <axis xyz="1 0 0"/>
    <limit effort="2" lower="0" upper="1.5707963267948966" velocity="2.0"/>
    <dynamics damping="0.1"/>
  </joint>

  <link name="lh_rfdistal">
    <inertial>
      <mass value="0.0"/>
      <origin xyz="0 0 0.0"/>
      <inertia ixx="0.0" ixy="0.0" ixz="0.0" iyy="0.0" iyz="0.0" izz="0.0"/>
    </inertial>
    <visual>
      <origin rpy="0.0 1.57079632679 1.57079632679" xyz="0.0 0.0 0.016"/>
      <geometry>
        <mesh filename="package://bio_tac/meshes/biotac/merged_tip.obj"/>
      </geometry>
    </visual>
    <collision>
      <origin rpy="0.0 1.57079632679 0.0" xyz="0.0 0.0 0.016"/>
        <geometry>
          <mesh filename="package://bio_tac/meshes/biotac/merged_tip.obj"/>
        </geometry>
    </collision>
  </link>

  <joint name="lh_RFJ1" type="revolute">
    <parent link="lh_rfmiddle"/>
    <child link="lh_rfdistal"/>
    <origin rpy="0 0 0" xyz="0 0 0.025"/>
    <axis xyz="1 0 0"/>
    <!-- standard distal joint -->
    <limit effort="2" lower="0" upper="1.5707963267948966" velocity="2.0"/>
    <dynamics damping="0.1"/>
  </joint>


  <link name="lh_rftip">
  </link>
  <joint name="lh_RFtip" type="fixed">
    <parent link="lh_rfdistal"/>
    <child link="lh_rftip"/>
    <origin rpy="0 0 0" xyz="0 0 0.026"/>
  </joint>

<!-- =================================================================================== -->
  <link name="lh_lfmetacarpal">
    <inertial>
      <origin rpy="0 0.0 0" xyz="0.0 0 0.0"/>
      <mass value="0.0"/>
      <inertia ixx="0.0" ixy="0.0" ixz="0.0" iyy="0.0" iyz="0.0" izz="0.0"/>
    </inertial>
    <visual>
      <!--origin rpy="0 -0.9599 0" xyz="0 0 0"/-->
      <origin rpy="-1.5707963 -0.9599 0" xyz="0 0 0"/>
      <geometry name="lh_lfmetacarpal_visual">
        <mesh filename="package://shadowhand/components/lf_metacarpal/lf_metacarpal_E3M5.dae" scale="-0.001 0.001 0.001"/>
      </geometry>
      <material name="LightGrey">
        <color rgba="0.7 0.7 0.7 1.0"/>
      </material>
    </visual>
    <collision>
      <!--origin rpy="0 -0.9599 0" xyz="-0.026986375 0 0.019"/-->
      <origin rpy="0 0 0" xyz="-0.026986375 0 0.019"/>
      <geometry name="lh_lfmetacarpal_collision_geom">
        <box size="0.018 0.024 0.040"/>
      </geometry>
    </collision>
  </link>
  <joint name="lh_LFJ5" type="revolute">
    <parent link="lh_palm"/>
    <child link="lh_lfmetacarpal"/>
    <origin rpy="0 0.9599 0" xyz="0.033 0 0.02071"/>
    <axis xyz="1 0 0"/>
    <limit effort="2" lower="0" upper="0.7853981633974483" velocity="2.0"/>
    <dynamics damping="0.1"/>
  </joint>

<!-- =================================================================================== -->
  <link name="lh_lfknuckle">
    <inertial>
      <origin rpy="0 0 0" xyz="0 0 0"/>
      <mass value="0.0"/>
      <inertia ixx="0.0" ixy="0.0" ixz="0.0" iyy="0.0" iyz="0.0" izz="0.0"/>
    </inertial>
    <visual>
      <origin rpy="0 0 0" xyz="0 0 0.0005"/>
      <geometry name="lh_lfknuckle_visual">
        <mesh filename="package://shadowhand/components/f_knuckle/f_knuckle_E3M5.dae" scale="0.001 0.001 0.001"/>
      </geometry>
      <material name="LightGrey"/>
    </visual>
    <collision>
      <origin rpy="0 1.5708 0" xyz="0 0 0"/>
      <geometry name="lh_lfknuckle_collision_geom">
        <cylinder length="0.014" radius="0.007"/>
      </geometry>
    </collision>
  </link>
  <joint name="lh_LFJ4" type="revolute">
    <parent link="lh_lfmetacarpal"/>
    <child link="lh_lfknuckle"/>
    <!--<origin xyz="0.033 0 0.095" rpy="0 0 0" />-->
    <origin rpy="0 -0.9599 0" xyz="-0.05397275 0 0.03779463"/>
    <axis xyz="0 -1 0"/>
    <limit effort="2" lower="-0.3490658503988659" upper="0.3490658503988659" velocity="2.0"/>
    <dynamics damping="0.1"/>
  </joint>

<!-- =================================================================================== -->
  <link name="lh_lfproximal">
    <inertial>
      <mass value="0.0"/>
      <origin xyz="0 0 0.0"/>
      <inertia ixx="0.0" ixy="0.0" ixz="0.0" iyy="0.0" iyz="0.0" izz="0.0"/>
    </inertial>
    <visual>
      <!--origin rpy="0 0 0" xyz="0 0 0"/-->
      <origin rpy="-1.5707963 0 0" xyz="0 0 0"/>
      <geometry name="lh_lfproximal_visual">
        <mesh filename="package://shadowhand/components/f_proximal/f_proximal_E3M5.dae" scale="0.001 0.001 0.001"/>
      </geometry>
      <material name="Grey"/>
    </visual>
    <collision>
      <origin rpy="0 0 0" xyz="0 0 0.025"/>
      <geometry name="lh_lfproximal_collision_geom">
        <cylinder length="0.040" radius="0.007"/>
      </geometry>
    </collision>
  </link>
  <joint name="lh_LFJ3" type="revolute">
    <parent link="lh_lfknuckle"/>
    <child link="lh_lfproximal"/>
    <origin rpy="0 0 0" xyz="0 0 0"/>
    <axis xyz="1 0 0"/>
    <limit effort="2" lower="-0.2617993877991494" upper="1.5707963267948966" velocity="2.0"/>
    <dynamics damping="0.1"/>
  </joint>

<!-- =================================================================================== -->
  <link name="lh_lfmiddle">
    <inertial>
      <origin rpy="0 0 0" xyz="0 0 0.0"/>
      <mass value="0.0"/>
      <inertia ixx="0.0" ixy="0.0" ixz="0.0" iyy="0.0" iyz="0.0" izz="0.0"/>
    </inertial>
    <visual>
      <!--origin rpy="0 0 0" xyz="0 0 0"/-->
      <origin rpy="-1.5707963 0 0" xyz="0 0 0"/>
      <geometry name="lh_lfmiddle_visual">
        <mesh filename="package://shadowhand/components/f_middle/f_middle_E3M5.dae" scale="0.001 0.001 0.001"/>
      </geometry>
      <material name="Grey"/>
    </visual>
    <collision>
      <origin rpy="0 0 0" xyz="0 0 0.0125"/>
      <geometry name="lh_lfmiddle_collision_geom">
        <cylinder length="0.025" radius="0.007"/>
      </geometry>
    </collision>
    <collision>
      <origin rpy="0 0 0" xyz="0 0 0.0"/>
      <geometry>
        <sphere radius="0.007"/>
      </geometry>
    </collision>
    <collision>
      <origin rpy="0 0 0" xyz="0 0 0.025"/>
      <geometry>
        <sphere radius="0.007"/>
      </geometry>
    </collision>
  </link>
  <joint name="lh_LFJ2" type="revolute">
    <parent link="lh_lfproximal"/>
    <child link="lh_lfmiddle"/>
    <origin rpy="0 0 0" xyz="0 0 0.045"/>
    <axis xyz="1 0 0"/>
    <limit effort="2" lower="0" upper="1.5707963267948966" velocity="2.0"/>
    <dynamics damping="0.1"/>
  </joint>



  <link name="lh_lfdistal">
    <inertial>
      <mass value="0.0"/>
      <origin xyz="0 0 0.0"/>
      <inertia ixx="0.0" ixy="0.0" ixz="0.0" iyy="0.0" iyz="0.0" izz="0.0"/>
    </inertial>
    <visual>
      <origin rpy="0.0 1.57079632679 1.57079632679" xyz="0.0 0.0 0.016"/>
      <geometry>
        <mesh filename="package://bio_tac/meshes/biotac/merged_tip.obj"/>
      </geometry>
    </visual>
    <collision>
      <origin rpy="0.0 1.57079632679 0.0" xyz="0.0 0.0 0.016"/>
        <geometry>
          <mesh filename="package://bio_tac/meshes/biotac/merged_tip.obj"/>
        </geometry>
    </collision>
  </link>

  <joint name="lh_LFJ1" type="revolute">
    <parent link="lh_lfmiddle"/>
    <child link="lh_lfdistal"/>
    <origin rpy="0 0 0" xyz="0 0 0.025"/>
    <axis xyz="1 0 0"/>
    <!-- standard distal joint -->
    <limit effort="2" lower="0" upper="1.5707963267948966" velocity="2.0"/>
    <dynamics damping="0.1"/>
  </joint>



  <link name="lh_lftip">
  </link>
  <joint name="lh_LFtip" type="fixed">
    <parent link="lh_lfdistal"/>
    <child link="lh_lftip"/>
    <origin rpy="0 0 0" xyz="0 0 0.026"/>
  </joint>

<!-- =================================================================================== -->
  <link name="lh_thbase">
    <inertial>
      <mass value="0.0"/>
      <origin rpy="0 0 0" xyz="0 0 0"/>
      <inertia ixx="0.0" ixy="0.0" ixz="0.0" iyy="0.0" iyz="0.0" izz="0.0"/>
    </inertial>
    <visual>
      <origin rpy="0 0 0" xyz="0 0 0"/>
      <geometry name="lh_thbase_visual">
        <box size="0.001 0.001 0.001"/>
      </geometry>
      <material name="shadow_thbase_material">
        <color rgba="0.5 0.5 0.5 1.0"/>
      </material>
    </visual>
    <collision>
      <origin rpy="0 0 0" xyz="0 0 0"/>
      <geometry name="lh_thbase_collision_geom">
        <sphere radius="0.011"/>
      </geometry>
    </collision>
  </link>
  <joint name="lh_THJ5" type="revolute">
    <parent link="lh_palm"/>
    <child link="lh_thbase"/>
    <origin rpy="-0.7853981633974483 0 1.5707963267948966" xyz="-0.034 -0.00858 0.029"/>
    <axis xyz="0 0 1"/>
    <limit effort="5.0" lower="-1.0471975511965976" upper="1.0471975511965976" velocity="4.0"/>
    <dynamics damping="0.2"/>
  </joint>

<!-- =================================================================================== -->
  <link name="lh_thproximal">
    <inertial>
      <mass value="0.0"/>
      <origin rpy="0 0 0" xyz="0 0 0.0"/>
      <inertia ixx="0.0" ixy="0.0" ixz="0.0" iyy="0.0" iyz="0.0" izz="0.0"/>
    </inertial>
    <visual>
      <!--origin rpy="0 0 1.5707963267948966" xyz="0 0 0"/-->
      <origin rpy="-1.5707963267948966 0 1.5707963267948966" xyz="0 0 0"/>
      <geometry name="lh_thproximal_visual">
        <mesh filename="package://shadowhand/components/th_proximal/th_proximal_E3M5.dae" scale="0.001 0.001 0.001"/>
      </geometry>
      <material name="shadow_thproximal_material">
        <color rgba="0.2 0.2 0.2 1.0"/>
      </material>
    </visual>
    <collision>
      <origin rpy="0 0 0" xyz="0 0 0.020"/>
      <geometry name="lh_thproximal_collision_geom">
        <cylinder length="0.018" radius="0.012"/>
      </geometry>
    </collision>
  </link>
  <joint name="lh_THJ4" type="revolute">
    <parent link="lh_thbase"/>
    <child link="lh_thproximal"/>
    <origin rpy="0 0 0" xyz="0 0 0"/>
    <axis xyz="0 -1 0"/>
    <limit effort="3" lower="0.0" upper="1.2217304763960306" velocity="4.0"/>
    <dynamics damping="0.2"/>
  </joint>

<!-- =================================================================================== -->
  <link name="lh_thhub">
    <inertial>
      <mass value="0.0"/>
      <origin rpy="0 0 0" xyz="0 0 0"/>
      <inertia ixx="0.0" ixy="0.0" ixz="0.0" iyy="0.0" iyz="0.0" izz="0.0   "/>
    </inertial>
    <visual>
      <origin rpy="0 0 0" xyz="0 0 0"/>
      <geometry name="lh_thhub_visual">
        <box size="0.001 0.001 0.001"/>
      </geometry>
      <material name="shadow_thhub_material">
        <color rgba="0.7 0.7 0.7 1.0"/>
      </material>
    </visual>
    <collision>
      <origin rpy="0 0 0" xyz="0 0 0"/>
      <geometry name="lh_thhub_collision_geom">
        <sphere radius="0.010"/>
      </geometry>
    </collision>
  </link>
  <joint name="lh_THJ3" type="revolute">
    <parent link="lh_thproximal"/>
    <child link="lh_thhub"/>
    <origin rpy="0 0 0" xyz="0 0 0.038"/>
    <axis xyz="0 -1 0"/>
    <limit effort="2.0" lower="-0.20943951023931953" upper="0.20943951023931953" velocity="4.0"/>
    <dynamics damping="0.2"/>
  </joint>

<!-- =================================================================================== -->
  <link name="lh_thmiddle">
    <inertial>
      <mass value="0.0"/>
      <origin rpy="0 0 0" xyz="0 0 0.0"/>
      <inertia ixx="0.0" ixy="0.0" ixz="0.0" iyy="0.0" iyz="0.0" izz="0.0"/>
    </inertial>
    <visual>
      <!--origin rpy="0 0 1.5707963267948966" xyz="0 0 0"/-->
      <origin rpy="-1.5707963267948966 0 1.5707963267948966" xyz="0 0 0"/>
      <geometry name="lh_thmiddle_visual">
        <mesh filename="package://shadowhand/components/th_middle/th_middle_E3M5.dae" scale="0.001 0.001 0.001"/>
      </geometry>
      <material name="shadow_thmiddle_material">
        <color rgba="0.2 0.2 0.2 1.0"/>
      </material>
    </visual>
    <collision>
      <origin rpy="0 0 0" xyz="0 0 0.012"/>
      <geometry name="lh_thmiddle_collision_geom">
        <cylinder length="0.018" radius="0.011"/>
      </geometry>
    </collision>
    <collision>
      <origin rpy="0 0 0" xyz="0 0 0.019"/>
      <geometry>
        <sphere radius="0.011"/>
      </geometry>
    </collision>
    <collision>
      <origin rpy="0 1.5708 0" xyz="0 0 0.032"/>
      <geometry>
        <cylinder length="0.014" radius="0.010"/>
      </geometry>
    </collision>
  </link>
  <joint name="lh_THJ2" type="revolute">
    <parent link="lh_thhub"/>
    <child link="lh_thmiddle"/>
    <origin rpy="0 0 0" xyz="0 0 0"/>
    <axis xyz="1 0 0"/>
    <limit effort="2.0" lower="-0.6981317007977318" upper="0.6981317007977318" velocity="2.0"/>
    <dynamics damping="0.1"/>
  </joint>


  <link name="lh_thdistal">
    <inertial>
      <mass value="0.0"/>
      <origin xyz="0 0 0.0"/>
      <inertia ixx="0.0" ixy="0.0" ixz="0.0" iyy="0.0" iyz="0.0" izz="0.0"/>
    </inertial>
    <visual>
      <origin rpy="0.0 1.57079632679 1.57079632679" xyz="0.0 0.0 0.016"/>
      <geometry>
        <mesh filename="package://bio_tac/meshes/biotac/merged_tip.obj"/>
      </geometry>
    </visual>
    <collision>
      <origin rpy="0.0 1.57079632679 0.0" xyz="0.0 0.0 0.016"/>
        <geometry>
          <mesh filename="package://bio_tac/meshes/biotac/merged_tip.obj"/>
        </geometry>
    </collision>
  </link>


  <joint name="lh_THJ1" type="revolute">
    <parent link="lh_thmiddle"/>
    <child link="lh_thdistal"/>
    <origin rpy="0 0 0" xyz="0 0 0.032"/>
    <axis xyz="1 0 0"/>
    <limit effort="1.0" lower="-0.2617993877991494" upper="1.5707963267948966" velocity="4.0"/>
    <dynamics damping="0.2"/>
  </joint>


  <link name="lh_thtip">
  </link>
  <joint name="lh_thtip" type="fixed">
    <parent link="lh_thdistal"/>
    <child link="lh_thtip"/>
    <origin rpy="0 0 0" xyz="0 0 0.0275"/>
  </joint>

</robot>

